<!-- description of the Canyonero robot, a robotics project for the UVic-UCC master -->
<robot name = "cambot">

	<!-- BASE-FOOTPRINT -->
	<!-- base_footprint is a fictitious link(frame) that is on the ground right below base_link origin, navigation stack depends on this frame -->
	<link name = "base_footprint"/>

	<joint name = "base_footprint_joint" type = "fixed">
		<parent link = "base_footprint"/>
		<child link = "base_link"/>
		<origin xyz = "0 0 2.04" rpy = "0 0 0"/>
	</joint>

	<!-- BASE-LINK -->
    <!--Actual body/chassis of the robot-->
	<link name = "base_link">
		<visual>
			<origin xyz = "0 0 0" rpy = "1.57 0 -1.57"/>
			<geometry>
				<mesh filename = "package://canyonero_description/meshes/canyonero_plates.stl"/>
			</geometry>
			<material name = "cambot/red">
				<color rgba = "1.0 0.0 0.0 0.75"/>
			</material>
		</visual>
		<!--collision>
      		<origin xyz = "0 0 0.12" rpy = "1.57 0 3.14"/>
      		<geometry>
        		<mesh filename = "package://cambot_description/meshes/cambot_base_collision.stl" scale="0.01 0.01 0.01"/>
      		</geometry>
    	</collision-->
		<inertial>
      		<origin rpy = "0 0 0" xyz = "174.84e-3 117.51e-3 -218.86e-3"/>
      		<mass value = "15.23"/>
      		<!-- inertia at cm or origin?-->
      		<inertia ixx = "0.016258"
               		 ixy = "0.000432"
               		 ixz="-0.000049"
               		 iyy="0.019275"
               		 iyz="0.000048"
               		 izz="0.016834"/>
    	</inertial>
	</link>

	<!-- WHEEL-JOINTS -->
	<joint name = "base_to_frontal_left_wheel" type = "continuous">
		<parent link = "base_link"/>
		<child link = "frontal_left_wheel_link"/>
		<origin xyz = "1.62 1.65 -1.05" rpy = "-1.57 0 0"/>
		<axis xyz = "0 0 1"/>
	</joint>

	<joint name = "base_to_frontal_right_wheel" type = "continuous">
		<parent link = "base_link"/>
		<child link = "frontal_right_wheel_link"/>
		<origin xyz = "1.62 -1.65 -1.05" rpy = "1.57 0 0"/>
		<axis xyz = "0 0 1"/>
	</joint>

	<joint name = "base_to_back_left_wheel" type = "continuous">
		<parent link = "base_link"/>
		<child link = "back_left_wheel_link"/>
		<origin xyz = "-1.62 1.65 -1.05" rpy = "-1.57 0 0"/>
		<axis xyz = "0 0 1"/>
	</joint>

	<joint name = "base_to_back_right_wheel" type = "continuous">
		<parent link = "base_link"/>
		<child link = "back_right_wheel_link"/>
		<origin xyz = "-1.62 -1.65 -1.05" rpy = "1.57 0 0"/>
		<axis xyz = "0 0 1"/>
	</joint>

	<!-- KINECT-JOINTS -->
	<joint name = "base_link_to_kinect" type = "fixed">
		<parent link = "base_link" />
		<child link = "kinect_link" />
		<origin xyz = "2.62 0 0.95" rpy = "0 0 0"/>
	</joint>

	<!-- WHEEL-LINKS -->
    <!--Actual wheels of the robot-->

	<link name = "frontal_left_wheel_link">
		<visual>
			<origin xyz = "0 0 0" rpy = "0 -1.57 0"/>
			<geometry>
				<mesh filename = "package://canyonero_description/meshes/canyonero_wheel.stl"/>
			</geometry>
			<material name = "cambot/black">
				<color rgba = "0.0 0.0 0.0 1.0"/>
			</material>
		</visual>
		<!--collision>
      		<origin xyz = "0 0 0.12" rpy = "1.57 0 3.14"/>
      		<geometry>
        		<mesh filename = "package://cambot_description/meshes/cambot_base_collision.stl" scale="0.01 0.01 0.01"/>
      		</geometry>
    	</collision-->
		<inertial>
      		<origin rpy = "0 0 0" xyz = "40.51e-3 38.66e-3 -54.98e-3"/>
      		<mass value = "15.23"/>
      		<!-- inertia at cm or origin?-->
      		<inertia ixx = "0.016258"
               		 ixy = "0.000432"
               		 ixz="-0.000049"
               		 iyy="0.019275"
               		 iyz="0.000048"
               		 izz="0.016834"/>
    	</inertial>
	</link>

	<link name = "frontal_right_wheel_link">
		<visual>
			<origin xyz = "0 0 0" rpy = "0 -1.57 0"/>
			<geometry>
				<mesh filename = "package://canyonero_description/meshes/canyonero_wheel.stl"/>
			</geometry>
			<material name = "cambot/black">
				<color rgba = "0.0 0.0 0.0 1.0"/>
			</material>
		</visual>
		<!--collision>
      		<origin xyz = "0 0 0.12" rpy = "1.57 0 3.14"/>
      		<geometry>
        		<mesh filename = "package://cambot_description/meshes/cambot_base_collision.stl" scale="0.01 0.01 0.01"/>
      		</geometry>
    	</collision-->
		<inertial>
      		<origin rpy = "0 0 0" xyz = "40.51e-3 38.66e-3 -54.98e-3"/>
      		<mass value = "15.23"/>
      		<!-- inertia at cm or origin?-->
      		<inertia ixx = "0.016258"
               		 ixy = "0.000432"
               		 ixz="-0.000049"
               		 iyy="0.019275"
               		 iyz="0.000048"
               		 izz="0.016834"/>
    	</inertial>
	</link>

	<link name = "back_left_wheel_link">
		<visual>
			<origin xyz = "0 0 0" rpy = "0 -1.57 0"/>
			<geometry>
				<mesh filename = "package://canyonero_description/meshes/canyonero_wheel.stl"/>
			</geometry>
			<material name = "cambot/black">
				<color rgba = "0.0 0.0 0.0 1.0"/>
			</material>
		</visual>
		<!--collision>
      		<origin xyz = "0 0 0.12" rpy = "1.57 0 3.14"/>
      		<geometry>
        		<mesh filename = "package://cambot_description/meshes/cambot_base_collision.stl" scale="0.01 0.01 0.01"/>
      		</geometry>
    	</collision-->
		<inertial>
      		<origin rpy = "0 0 0" xyz = "40.51e-3 38.66e-3 -54.98e-3"/>
      		<mass value = "15.23"/>
      		<!-- inertia at cm or origin?-->
      		<inertia ixx = "0.016258"
               		 ixy = "0.000432"
               		 ixz="-0.000049"
               		 iyy="0.019275"
               		 iyz="0.000048"
               		 izz="0.016834"/>
    	</inertial>
	</link>

	<link name = "back_right_wheel_link">
		<visual>
			<origin xyz = "0 0 0" rpy = "0 -1.57 0"/>
			<geometry>
				<mesh filename = "package://canyonero_description/meshes/canyonero_wheel.stl"/>
			</geometry>
			<material name = "cambot/black">
				<color rgba = "0.0 0.0 0.0 1.0"/>
			</material>
		</visual>
		<!--collision>
      		<origin xyz = "0 0 0.12" rpy = "1.57 0 3.14"/>
      		<geometry>
        		<mesh filename = "package://cambot_description/meshes/cambot_base_collision.stl" scale="0.01 0.01 0.01"/>
      		</geometry>
    	</collision-->
		<inertial>
      		<origin rpy = "0 0 0" xyz = "40.51e-3 38.66e-3 -54.98e-3"/>
      		<mass value = "15.23"/>
      		<!-- inertia at cm or origin?-->
      		<inertia ixx = "0.016258"
               		 ixy = "0.000432"
               		 ixz="-0.000049"
               		 iyy="0.019275"
               		 iyz="0.000048"
               		 izz="0.016834"/>
    	</inertial>
	</link>

	<!-- KINECT-LINK -->
	<!-- Actual kinect of the robot -->
	<link name = "kinect_link">
		<!--visual>
			<origin xyz = "0 0 0" rpy = "1.57 0 1.57" />
			<geometry>
				<mesh filename = "package://cambot_description/meshes/cambot_camera.stl" />
			</geometry>
			<material name = "cambot/black">
				<color rgba = "0.0 0.0 0.0 1.0" />
			</material>
		</visual>
		<collision>
      		<origin xyz = "0 0 0" rpy = "1.57 0 1.57" />
      		<geometry>
        		<mesh filename = "package://cambot_description/meshes/cambot_camera_collision.stl" scale="0.01 0.01 0.01"/>
      		</geometry>
    	</collision>
		<inertial>
      		<origin rpy = "0 0 0" xyz = "7.035e-3 -70.134e-3 -87.744e-3"/>
      		<mass value = "0.0458425"/>
      		<inertia ixx = "0.001351"
               ixy = "0.000000"
               ixz="0.000000"
               iyy="0.000886"
               iyz="-0.000026"
               izz="0.001635"/>
    	</inertial-->
	</link>

</robot>